Workbook

Sheet Revision
A1: Version | B1: Date | C1: Remark
A2: V1.0 | B2: 42674 | C2: Create
A3: V1.1 | B3: 42685 | C3: 1、change chip name ==> SC2721G 2、Update ball name： K3：VSS_TSX change to VSS_TSX_1 M2：VSS_TSX change to VSS_TSX_2 N3：VSS_TSX change to VSS_TSX_3 L11:FLSH_IB change to FLASH_IB
A4: V1.2 | B4: 43635 | C4: Update ball description(M3)

Sheet Ball map
B1: 1 | C1: 2 | D1: 3 | E1: 4 | F1: 5 | G1: 6 | H1: 7 | I1: 8 | J1: 9 | K1: 10 | L1: 11 | M1: 12 | N1: 13 | O1: 14 | P1: 15
A2: A | B2: NC | C2: VBAT_DRV | D2: VBAT_DRV | E2: LX_CPU | F2: LX_CPU | G2: LX_CORE | H2: LX_CORE | I2: VBAT_DRV | J2: ADI_D | L2: AUD_ADD0 | M2: AUD_SCLK | O2: EXT_XTL_EN2 | P2: NC | Q2: A
A3: B | B3: LX_GEN1V85 | C3: VBAT_DRV | D3: VBAT_DRV | E3: VSS_DRV | F3: LX_CPU | G3: VSS_DRV | H3: LX_CORE | I3: VBAT_DRV | J3: AUD_DASYNC | K3: AUD_ADSYNC | L3: DCDC_CPU_EN | M3: EXT_XTL_EN0 | N3: EXT_XTL_EN1 | O3: EXT_XTL_EN3 | P3: LX_WPA | Q3: B
A4: C | B4: LX_GEN1V4 | C4: LX_GEN1V4 | E4: VSS_DRV | G4: VSS_DRV | J4: AUD_DAD0 | L4: ANA_INT | M4: EXT_RST_B | O4: VBAT_DRV | P4: VBAT_DRV | Q4: C
A5: D | B5: AVDD18 | C5: VDDCAMIO | D5: VSS_DRV | E5: FB_CPU | F5: VSS_DRV | G5: VSS_DRV | H5: FB_CORE_N | I5: FB_CORE | J5: ADI_SCLK | K5: AUD_DAD1 | L5: CLK32K | M5: CHIP_SLEEP | N5: WPA_APCIN | O5: VSS_DRV | P5: VSS_DRV | Q5: D
A6: E | C6: VDDMEM_FB | E6: FB_CPU_N | F6: VSS_DRV | H6: PBINT2 | J6: T_DIG | L6: FB_WPA | M6: VDDSIM1 | N6: PTESTO | O6: VDDSIM0 | P6: VDDCAMMOT | Q6: E
A7: F | B7: VDDMEM | C7: VDDRF18 | D7: RTC_MODE | E7: OPTION | I7: PBINT | J7: PRODT | K7: VBATA | L7: VBATA | M7: VDDCAMA | O7: VDDUSB33 | Q7: F
A8: G | B8: 32K_KO | C8: 32K_KI | E8: VDDRF1V25 | F8: VDCDC_GEN1V85 | H8: VSS | I8: VSS | J8: VSS | K8: VBATA | L8: VBATA | M8: VDDEMMCCORE | N8: VDDSD | O8: VDDSDIO | P8: VDD28 | Q8: G
A9: H | C9: VBAT_BK | E9: VDDCON | F9: VDCDC_GEN1V4 | G9: VDCDC_GEN1V4 | H9: VBATB | I9: VSS | J9: VSS | M9: ADCI2 | N9: ADCI3 | O9: VDDSIM2 | P9: VDDWIFIPA | Q9: H
A10: J | B10: DCXO_LOWCUR | C10: VDDRTC | D10: VDDDCXO | E10: VDDCAMD | H10: AGND_VB | I10: AGND_VBO | J10: VSS | K10: BAT_DET | L10: ADCI1 | M10: ADCI4 | O10: VPP | Q10: J
A11: K | B11: XTAL_OUT | C11: XTAL_IN | D11: VSS_TSX_1 | E11: TSEN_VREFP | I11: HEADSET_L_INT | J11: RCV_P | M11: EXTRSTN | N11: CHG_PD | O11: DMIN | P11: DPIN | Q11: K
A12: L | C12: CLK26M | E12: TSEN_IN | F12: TSEN_VREFN | G12: MIC2_N | H12: MIC2_P | I12: HEADMIC_IN_DET | J12: RCV_N | K12: CC1 | L12: FLASH_IB | M12: SW | N12: RGB_IB0 | O12: DMOUT | P12: DPOUT | Q12: L
A13: M | B13: REF_OUT0 | C13: VSS_TSX_2 | D13: TSX_MODE | F13: MIC_BIAS | G13: HEADMIC_BIAS | I13: AVDD_VBO | J13: VSS_PA | L13: CC2 | N13: RGB_IB1 | O13: RGB_IB2 | Q13: M
A14: N | B14: REF_OUT1 | C14: REF_OUT2 | D14: VSS_TSX_3 | E14: AVDD_VB | F14: HEADMIC_N | G14: HEADMIC_P | H14: MIC1_P | I14: HP_R | J14: SPK_P | K14: SPK_N | L14: VDDVIBR | M14: SENSE_N | N14: SENSE_P | O14: VCHG | P14: VDRV | Q14: N
A15: P | B15: NC | C15: REF_OUT3 | E15: VBAT_AUD | F15: AMP_VCOM | H15: MIC1_N | I15: HP_L | K15: VBAT_PA | L15: VDDKPLED | N15: ISENSE | O15: VBAT_SENSE | P15: NC | Q15: P
B16: 1 | C16: 2 | D16: 3 | E16: 4 | F16: 5 | G16: 6 | H16: 7 | I16: 8 | J16: 9 | K16: 10 | L16: 11 | M16: 12 | N16: 13 | O16: 14 | P16: 15

Sheet Ball Description
A1: Ball No. | B1: Ball Name | C1: Description
A2: Audio analog interface
A3: M5 | B3: MIC_BIAS | C3: Microphone Bias LDO output
A4: N7 | B4: MIC1_P | C4: Microphone1 positive input
A5: P7 | B5: MIC1_N | C5: Microphone1 negative input
A6: L7 | B6: MIC2_P | C6: Microphone2 positive input
A7: L6 | B7: MIC2_N | C7: Microphone2 negative input
A8: M6 | B8: HEADMIC_BIAS | C8: Headphone Bias LDO output
A9: N5 | B9: HEADMIC_N | C9: Headphone microphone negative input
A10: N6 | B10: HEADMIC_P | C10: Headphone microphone positive input
A11: L8 | B11: HEADMIC_IN_DET | C11: Headphone button detect
A12: K8 | B12: HEADSET_L_INT | C12: Headphone insert detect
A13: N8 | B13: HP_R | C13: Headphone right output
A14: P8 | B14: HP_L | C14: Headphone left output
... A26: M9 | B26: VSS_PA | C26: Audio speaker PA ground
A27: ADI Interface
A28: D9 | B28: ADI_SCLK | C28: ADI interface synchronize clock
A29: A9 | B29: ADI_D | C29: ADI interface synchronize data
A30: Audio digital interface
A31: A12 | B31: AUD_SCLK | C31: Audio interface synchronize clock
A32: B10 | B32: AUD_ADSYNC | C32: Audio interface RX data synchronize signal
A33: A11 | B33: AUD_ADD0 | C33: Audio interface RX data
A34: B9 | B34: AUD_DASYNC | C34: Audio interface TX data synchronize signal
A35: C9 | B35: AUD_DAD0 | C35: Audio interface TX data bit0
A36: D10 | B36: AUD_DAD1 | C36: Audio interface TX data bit1
A37: A to D interface
A38: C12 | B38: EXT_RST_B | C38: Adie reset Ddie,low active
A39: C11 | B39: ANA_INT | C39: Adie interrupt to Ddie,high active
A40: D12 | B40: CHIP_SLEEP | C40: Adie into deepsleep mode input signal,high active
A41: D11 | B41: CLK32K | C41: Adie output to Ddie,32K clock
A42: E13 | B42: PTESTO | C42: Adie output to Ddie,product test mode
A43: L2 | B43: CLK26M | C43: Adie 26M clock input
A44: B11 | B44: DCDC_CPU_EN | C44: DCDCCPU enable input
A45: B12 | B45: EXT_XTL_EN0 | C45: External wake up input0
A46: B13 | B46: EXT_XTL_EN1 | C46: External wake up input1
A47: A14 | B47: EXT_XTL_EN2 | C47: External wake up input2
A48: B14 | B48: EXT_XTL_EN3 | C48: External wake up input3
A49: 32K interface
A50: G1 | B50: 32K_KO | C50: 32K crystal clock output,32K clock input when 32K-Less
A51: G2 | B51: 32K_KI | C51: 32K crystal clock input
...

Sheet Ball location
A1: Ball No. | B1: Ball Name | C1: Coordinates
C2: X | D2: Y
A3: A14 | B3: EXT_XTL_EN2 | C3: 2.4 | D3: 2.6
A4: B14 | B4: EXT_XTL_EN3 | C4: 2.4 | D4: 2.2
A5: D9 | B5: ADI_SCLK | C5: 0.4 | D5: 1.4
A6: A9 | B6: ADI_D | C6: 0.4 | D6: 2.6
A7: A12 | B7: AUD_SCLK | C7: 1.6 | D7: 2.6
A8: B10 | B8: AUD_ADSYNC | C8: 0.8 | D8: 2.2
A9: A11 | B9: AUD_ADD0 | C9: 1.2 | D9: 2.6
A10: B9 | B10: AUD_DASYNC | C10: 0.4 | D10: 2.2
A11: C9 | B11: AUD_DAD0 | C11: 0.4 | D11: 1.8
A12: D10 | B12: AUD_DAD1 | C12: 0.8 | D12: 1.4
A13: C12 | B13: EXT_RST_B | C13: 1.6 | D13: 1.8
A14: C11 | B14: ANA_INT | C14: 1.2 | D14: 1.8
... A168: P14 | B168: VBAT_SENSE | C168: 2.4 | D168: -2.6

Sheet test
A1: Ball map name | D1: Pin list ball name
A2: W36 | B2: ADI_D | D2: ADI_D | F2: =IF(B2=test!D2,"OK","F") -> OK
A3: W35 | B3: ADI_SCLK | D3: ADI_SCLK | F3: =IF(B3=test!D3,"OK","F") -> OK
A4: U33 | B4: ANA_INT | D4: ANA_INT | F4: =IF(B4=test!D4,"OK","F") -> OK
A5: K8 | B5: APCOUT0 | D5: APCOUT0 | F5: =IF(B5=test!D5,"OK","F") -> OK
A6: L8 | B6: APCOUT1 | D6: APCOUT1 | F6: =IF(B6=test!D6,"OK","F") -> OK
A7: H9 | B7: APCOUT2 | D7: APCOUT2 | F7: =IF(B7=test!D7,"OK","F") -> OK
A8: U36 | B8: AUD_ADD0 | D8: AUD_ADD0 | F8: =IF(B8=test!D8,"OK","F") -> OK
A9: V37 | B9: AUD_ADSYNC | D9: AUD_ADSYNC | F9: =IF(B9=test!D9,"OK","F") -> OK
A10: W34 | B10: AUD_DAD0 | D10: AUD_DAD0 | F10: =IF(B10=test!D10,"OK","F") -> OK
A11: W33 | B11: AUD_DAD1 | D11: AUD_DAD1 | F11: =IF(B11=test!D11,"OK","F") -> OK
A12: V36 | B12: AUD_DASYNC | D12: AUD_DASYNC | F12: =IF(B12=test!D12,"OK","F") -> OK
A13: T36 | B13: AUD_SCLK | D13: AUD_SCLK | F13: =IF(B13=test!D13,"OK","F") -> OK
... A216: D36 | B216: MTMS_ARM | D216: MTMS_ARM | F216: =IF(B216=test!D216,"OK","F") -> OK
A217: A3 | B217: POP_1V1 | F217: =IF(B217=test!D217,"OK","F") -> F | G217: POP DDR ，可忽略
A218: AU32 | B218: POP_1V8 | F218: =IF(B218=test!D218,"OK","F") -> F | G218: POP DDR ，可忽略
A219: C20 | B219: POP_ZQ0_A | F219: =IF(B219=test!D219,"OK","F") -> F | G219: POP DDR ，可忽略
A220: B18 | B220: POP_ZQ0_C | F220: =IF(B220=test!D220,"OK","F") -> F | G220: POP DDR ，可忽略
A221: A19 | B221: POP_ZQ1_A | F221: =IF(B221=test!D221,"OK","F") -> F | G221: POP DDR ，可忽略
A222: B19 | B222: POP_ZQ1_C | F222: =IF(B222=test!D222,"OK","F") -> F
A223: D35 | B223: PTEST | D223: PTEST | F223: =IF(B223=test!D223,"OK","F") -> OK
A224: G33 | B224: PWMA | D224: PWMA | F224: =IF(B224=test!D224,"OK","F") -> OK
A225: D1 | B225: RF_LVDS0_ADC_ON | D225: RF_LVDS0_ADC_ON | F225: =IF(B225=test!D225,"OK","F") -> OK
A226: D2 | B226: RF_LVDS0_DAC_ON | D226: RF_LVDS0_DAC_ON | F226: =IF(B226=test!D226,"OK","F") -> OK
A227: B7 | B227: RF_LVDS1_ADC_ON | D227: RF_LVDS1_ADC_ON | F227: =IF(B227=test!D227,"OK","F") -> OK
A228: A7 | B228: RF_LVDS1_DAC_ON | D228: RF_LVDS1_DAC_ON | F228: =IF(B228=test!D228,"OK","F") -> OK
A229: R6 | B229: RFCTL0 | D229: RFCTL0 | F229: =IF(B229=test!D229,"OK","F") -> OK
A230: T6 | B230: RFCTL1 | D230: RFCTL1 | F230: =IF(B230=test!D230,"OK","F") -> OK
A231: P3 | B231: RFCTL10 | D231: RFCTL10 | F231: =IF(B231=test!D231,"OK","F") -> OK
A232: R5 | B232: RFCTL11 | D232: RFCTL11 | F232: =IF(B232=test!D232,"OK","F") -> OK
A233: M6 | B233: RFCTL12 | D233: RFCTL12 | F233: =IF(B233=test!D233,"OK","F") -> OK
A234: P6 | B234: RFCTL13 | D234: RFCTL13 | F234: =IF(B234=test!D234,"OK","F") -> OK
... A356: AT20 | B356: VEMMCIO | D356: VEMMCIO | F356: =IF(B356=test!D356,"OK","F") -> OK
A357: R31 | B357: VFB_VDDARM_N | F357: =IF(B357=test!D357,"OK","F") -> F | G357: 可忽略
A358: T31 | B358: VFB_VDDARM_P | F358: =IF(B358=test!D358,"OK","F") -> F | G358: 可忽略
A359: P31 | B359: VFB_VDDCORE_N | F359: =IF(B359=test!D359,"OK","F") -> F | G359: 可忽略
A360: N31 | B360: VFB_VDDCORE_P | F360: =IF(B360=test!D360,"OK","F") -> F | G360: 可忽略
A361: J37 | B361: VIO_CTP | D361: VIO_CTP | F361: =IF(B361=test!D361,"OK","F") -> OK
A362: H37 | B362: VIO18 | D362: VIO18 | F362: =IF(B362=test!D362,"OK","F") -> OK
A363: M37 | B363: VIO18 | D363: VIO18 | F363: =IF(B363=test!D363,"OK","F") -> OK
...
